Workbook

Sheet MSBP Consolidated Plan
A1: No | B1: Category | C1: Task / Project | D1: Code | E1: Project Name | F1: Project Lead | G1: Team Collaboration | H1: Progress | I1: Target Date | J1: Start Date | K1: End Date | L1: Status | M1: History Work Accomplishment | N1: Plan Activities (Weekly) | O1: Issue (Risk) | P1: Delay | Q1: User | R1: Folder Link | S1: Lead Email | T1: Collaboration Team Email | U1: Count Project by Name | V1: Column22 | W1: Column21 | X1: Category2 | Y1: NEED 3rd PARTY (Admin) | Z1: PLAN START | AA1: PLAN END | AB1: PLAN DATE | AC1: Effectiv Year
A2: 1 | B2: Management System | C2: ITM Integrated Management System (TIMES) Establishment -Site Level | D2: MS 1.1 | E2: TIMES QMS Deployment - Melak Cluster (Establishment) | F2: ALR | G2: ARS, RRP | H2: 0.85 | I2: 46022 | J2: 45348 | K2: 46022 | L2: Hold | M2: 1. Already conducted Stage 1 (BP Workshop) 2. Already conducted Stage 2 (MS Workshop) 3. Already conducted review and alignment for the BP Design 4. Already coordinate and remind target with DSPM - for operational basis in SOP development 5. Already conducted further discussion regarding Coal Processing process - align with IBU 6. Already conducted socialization agenda to All TCM-BEK related stakeholders regarding BP Level 0 Mapping 7. Already continued the project by giving the TCM & BEK BP to Consultant Team 8. Already ensure and monitor the implementation of MELAK BP Development by Consultant Team | N2: 1. Ensure the socialization of the final deliverables of MELAK BP to all MELAK respective stakeholders 2. Implement the next phase of Governance development | O2: N/A | P2: =Project_Tracker[[#This Row],[End Date]]-Project_Tracker[[#This Row],[Target Date]] -> 0 | S2: =IF(Project_Tracker[[#This Row],[Project Lead]]="", "", IFERROR(VLOOKUP(Project_Tracker[[#This Row],[Project Lead]], Setting!C:D, 2, 0), "")) -> aldy_rienaldy@banpuindo.co.id | U2: =Project_Tracker[[#This Row],[Project Lead]]&", "&Project_Tracker[[#This Row],[Team Collaboration]] -> ALR, ARS, RRP | AC2: 2025
A3: 2 | B3: Management System | C3: ITM Integrated Management System (TIMES) Establishment -Site Level | D3: MS 1.2 | E3: TIMES QMS Deployment - JBG (Establishment) | F3: RRP | G3: ALR, DHI | H3: 0 | I3: H1-H2 | L3: Open | O3: Need confirmation with JBG | S3: =IF(Project_Tracker[[#This Row],[Project Lead]]="", "", IFERROR(VLOOKUP(Project_Tracker[[#This Row],[Project Lead]], Setting!C:D, 2, 0), "")) -> ratih_putri@banpuindo.co.id | U3: =Project_Tracker[[#This Row],[Project Lead]]&", "&Project_Tracker[[#This Row],[Team Collaboration]] -> RRP, ALR, DHI | AC3: 2025
A4: 3 | B4: Management System | C4: ITM Integrated Management System (TIMES) Establishment -Site Level | D4: MS 1.3 | E4: TIMES QMS - TRUST (Establishment) | F4: ARS | G4: ALR, DHI, RRP | H4: 0 | I4: Q3-H2 | L4: Open | O4: Still waiting key deliverables of Katulistiwa Project | S4: =IF(Project_Tracker[[#This Row],[Project Lead]]="", "", IFERROR(VLOOKUP(Project_Tracker[[#This Row],[Project Lead]], Setting!C:D, 2, 0), "")) -> aditya_r@banpuindo.co.id | U4: =Project_Tracker[[#This Row],[Project Lead]]&", "&Project_Tracker[[#This Row],[Team Collaboration]] -> ARS, ALR, DHI, RRP | AC4: 2025
A5: 4 | B5: Management System | C5: ITM Integrated Management System (TIMES) Element/Standard Deployment | D5: MS 2.1 | E5: Strategy & Performance Management | F5: ALR | H5: 1 | I5: 45838 | J5: 45474 | K5: 45838 | L5: Completed | M5: 1. Already identified the requirements for the Management Standards 2. Already drafted for the Management Standard 3. Already Followed-up the 1st review result from PO 4. Conduct 2nd review from MSBP Head 5. Conduct 3rd review from ERSM Head 6. Conduct Alignment Meeting with related stakeholders in Subsidiaries 7. Finetune the Management Standard Document | N5: 1. Conduct the approval for the MS Documents | O5: N/A | P5: =Project_Tracker[[#This Row],[End Date]]-Project_Tracker[[#This Row],[Target Date]] -> 0 | S5: =IF(Project_Tracker[[#This Row],[Project Lead]]="", "", IFERROR(VLOOKUP(Project_Tracker[[#This Row],[Project Lead]], Setting!C:D, 2, 0), "")) -> aldy_rienaldy@banpuindo.co.id | U5: =Project_Tracker[[#This Row],[Project Lead]]&", "&Project_Tracker[[#This Row],[Team Collaboration]] -> ALR, | AC5: 2025
A6: 5 | B6: Management System | C6: ITM Integrated Management System (TIMES) Element/Standard Deployment | D6: MS 2.2 | E6: TIMES QAR/Auditing Management | F6: RRP | G6: ALR | H6: 0.9 | I6: Q2-H1 | L6: Progress | M6: 1. Already reviewed MS Auditing Management that already updated by Excellence Team to be MS Assurance Management System 2. Already communicate Detail Context of Management Standard to DSPM/SPM/MS & HSEC/CD all sites on 7 May 2025 | N6: 1. Communicate Management Standard to Site Management and Function Head Related all sites 2. Getting approval MS Document | S6: =IF(Project_Tracker[[#This Row],[Project Lead]]="", "", IFERROR(VLOOKUP(Project_Tracker[[#This Row],[Project Lead]], Setting!C:D, 2, 0), "")) -> ratih_putri@banpuindo.co.id | U6: =Project_Tracker[[#This Row],[Project Lead]]&", "&Project_Tracker[[#This Row],[Team Collaboration]] -> RRP, ALR | AC6: 2025
A7: 7 | B7: Management System | C7: ITM Integrated Management System (TIMES) Element/Standard Deployment | D7: MS 2.4 | E7: ESG | F7: ALR | G7: ASN, RRP | H7: 1 | I7: 46022 | J7: 45537 | K7: 46022 | L7: Completed | M7: 1. Already showed to SD regarding ESG ownership mapping to the Business Process 2. Already reviewed the mapping result 3. Already conducted the Kick-Off Meeting 4. Already explained to SD PO regarding TIMES 5. Identify the ESG Priority (Requirement to be set-up for the governance pointing to BP) in 2025 6. Already developed the ESG requirements based on ESG Topics 7. Already reviewed all ESG Requirements based on ESG Sub Topics 8. Already mapped the priority requirement to the Business Process (as the ownership) 9. Already set up the roadmap 10. Finetuning communication materials 11. Plan the Communication Strategy | N7: 1. Present the Roadmap to the related stakeholders 2. Finetuning the review results for the roadmap 3. Present the roadmap and initiative for the 2nd Phase | O7: N/A | P7: =Project_Tracker[[#This Row],[End Date]]-Project_Tracker[[#This Row],[Target Date]] -> 0 | S7: =IF(Project_Tracker[[#This Row],[Project Lead]]="", "", IFERROR(VLOOKUP(Project_Tracker[[#This Row],[Project Lead]], Setting!C:D, 2, 0), "")) -> aldy_rienaldy@banpuindo.co.id | U7: =Project_Tracker[[#This Row],[Project Lead]]&", "&Project_Tracker[[#This Row],[Team Collaboration]] -> ALR, ASN, RRP | AC7: 2025
A8: 8 | B8: Management System | C8: ITM Integrated Management System (TIMES) Element/Standard Deployment | D8: MS 2.5 | E8: Security Management (ITM + SITES) | F8: ARS | G8: DHI | H8: 1 | I8: Q2-H1 | L8: Completed | M8: Policy and Management Standard still on review by MSBP Head | N8: To align SOP on ITM Level with Site level | S8: =IF(Project_Tracker[[#This Row],[Project Lead]]="", "", IFERROR(VLOOKUP(Project_Tracker[[#This Row],[Project Lead]], Setting!C:D, 2, 0), "")) -> aditya_r@banpuindo.co.id | U8: =Project_Tracker[[#This Row],[Project Lead]]&", "&Project_Tracker[[#This Row],[Team Collaboration]] -> ARS, DHI | AC8: 2025
A9: 9 | B9: Management System | C9: ITM Integrated Management System (TIMES) Element/Standard Deployment | D9: MS 2.6 | E9: Management Review (MR) | F9: ALR | G9: RRP | H9: 0.85 | I9: 45838 | J9: 45474 | K9: 45838 | L9: Progress | M9: 1. Already developed the Management Standard (MR) | N9: 1. Conduct communication and alignment meeting with Counterpart 2. Finetune and Approval | O9: N/A | P9: =Project_Tracker[[#This Row],[End Date]]-Project_Tracker[[#This Row],[Target Date]] -> 0 | S9: =IF(Project_Tracker[[#This Row],[Project Lead]]="", "", IFERROR(VLOOKUP(Project_Tracker[[#This Row],[Project Lead]], Setting!C:D, 2, 0), "")) -> aldy_rienaldy@banpuindo.co.id | U9: =Project_Tracker[[#This Row],[Project Lead]]&", "&Project_Tracker[[#This Row],[Team Collaboration]] -> ALR, RRP | AC9: 2025
A10: 10 | B10: Management System | C10: ITM Integrated Management System (TIMES) Element/Standard Deployment | D10: MS 2.7 | E10: Community Development | F10: DHI | G10: ALR | H10: 0 | I10: 45838 | L10: Hold | S10: =IF(Project_Tracker[[#This Row],[Project Lead]]="", "", IFERROR(VLOOKUP(Project_Tracker[[#This Row],[Project Lead]], Setting!C:D, 2, 0), "")) -> dhany_indraswara@banpuindo.co.id | U10: =Project_Tracker[[#This Row],[Project Lead]]&", "&Project_Tracker[[#This Row],[Team Collaboration]] -> DHI, ALR | AC10: 2025
A11: 11 | B11: Management System | C11: ITM Integrated Management System (TIMES) Element/Standard Deployment | D11: MS 2.8 | E11: Procurement/SCM | F11: ALR | G11: RRP | H11: 1 | I11: 45838 | J11: 45590 | K11: 45838 | L11: Completed | M11: 1. Already confirmed the project objective and scope 2. Aleady identified the requirements for Procedure Development 3. Already draft the Management Standard Documents 4. Already developed other requirements for Management Standard (collaborate with PO) 5. Alignment with Mahakam Leading Practice 6. Conduct alignment with Legal regarding contract 7. Done for final review and finalization of Management Standard | N11: 1. Conduct sircular approval of documents | O11: N/A | P11: =Project_Tracker[[#This Row],[End Date]]-Project_Tracker[[#This Row],[Target Date]] -> 0 | S11: =IF(Project_Tracker[[#This Row],[Project Lead]]="", "", IFERROR(VLOOKUP(Project_Tracker[[#This Row],[Project Lead]], Setting!C:D, 2, 0), "")) -> aldy_rienaldy@banpuindo.co.id | U11: =Project_Tracker[[#This Row],[Project Lead]]&", "&Project_Tracker[[#This Row],[Team Collaboration]] -> ALR, RRP | AC11: 2025
A12: 12 | B12: Management System | C12: ITM Integrated Management System (TIMES) Element/Standard Deployment | D12: MS 2.9 | E12: Change Management | F12: RRP | G12: ASN | H12: 0 | I12: H1-H2 | L12: Open | S12: =IF(Project_Tracker[[#This Row],[Project Lead]]="", "", IFERROR(VLOOKUP(Project_Tracker[[#This Row],[Project Lead]], Setting!C:D, 2, 0), "")) -> ratih_putri@banpuindo.co.id | U12: =Project_Tracker[[#This Row],[Project Lead]]&", "&Project_Tracker[[#This Row],[Team Collaboration]] -> RRP, ASN | AC12: 2025
A13: 13 | B13: Management System | C13: ITM Integrated Management System (TIMES) Element/Standard Deployment | D13: MS 2.1 | E13: Information Technology | F13: DHI | G13: ARS | H13: 0 | I13: 46015 | L13: Open | O13: Waiting IT organization establishment | S13: =IF(Project_Tracker[[#This Row],[Project Lead]]="", "", IFERROR(VLOOKUP(Project_Tracker[[#This Row],[Project Lead]], Setting!C:D, 2, 0), "")) -> dhany_indraswara@banpuindo.co.id | U13: =Project_Tracker[[#This Row],[Project Lead]]&", "&Project_Tracker[[#This Row],[Team Collaboration]] -> DHI, ARS | AC13: 2025
A14: 14 | B14: Management System | D14: MS 3 | E14: Management System Communication | F14: ALR | G14: ARS, RRP, DHI | H14: 1 | I14: 46021 | J14: 45689 | K14: 46021 | L14: Completed | M14: 1. Already drafted for the MOTION Agenda 2. Aleady conducted discussion with peers regarding draft of MOTION Agenda 3. Already informed the Motion Plan Series update to MSBP Head 4. Already send the 3rd Motion Series | N14: 1. Implement for regular motion agenda | O14: N/A | P14: =Project_Tracker[[#This Row],[End Date]]-Project_Tracker[[#This Row],[Target Date]] -> 0 | S14: =IF(Project_Tracker[[#This Row],[Project Lead]]="", "", IFERROR(VLOOKUP(Project_Tracker[[#This Row],[Project Lead]], Setting!C:D, 2, 0), "")) -> aldy_rienaldy@banpuindo.co.id | U14: =Project_Tracker[[#This Row],[Project Lead]]&", "&Project_Tracker[[#This Row],[Team Collaboration]] -> ALR, ARS, RRP, DHI | AC14: 2025
A15: 15 | B15: Management System | D15: MS 4 | E15: ITM Business Process Highlevel and its implementation | F15: ASN | G15: ALR, ARS, RRP, DHI | H15: 0.95 | I15: Q2-H1 | J15: 45699 | K15: 45777 | L15: Progress | M15: Actual project completion (80%) is calculated as of April 29th, 2025. - Most project activities in the tenth week have been focused on Conducting workshops, Gathering additional inputs and data, Discussed with workshop - All workshops are currently in completed - The current progressing tasks include target operating model design (70%). - Follow-up for Final Outcomes and preparation SteerCo and Sponsor Meeting. | S15: =IF(Project_Tracker[[#This Row],[Project Lead]]="", "", IFERROR(VLOOKUP(Project_Tracker[[#This Row],[Project Lead]], Setting!C:D, 2, 0), "")) -> andri_s@banpuindo.co.id | U15: =Project_Tracker[[#This Row],[Project Lead]]&", "&Project_Tracker[[#This Row],[Team Collaboration]] -> ASN, ALR, ARS, RRP, DHI | AC15: 2025
A16: 16 | B16: Management System | C16: BP-Organization Alignment and QMS as aggreed planned (based on the poin 4) | D16: MS 5.1 | E16: Finance & Accounting | F16: ALR | G16: ARS | H16: 1 | I16: 45670 | J16: 45461 | K16: 45670 | L16: Completed | M16: 1. Already developed BP L2-3 FA 2. Already developed Detail Flow Process + RASCI 3. Already reviewed BP & Flow Process by Process Owner 4. Already conducted BP review with Finance Director 5. Already designed the propose Organization Structure (with HR) 6. Already sent Project Closing + Deliverables to related stakeholders | N16: 1. Conduct Approval on BP Design (Waiting HRMC Results) | O16: N/A | P16: =Project_Tracker[[#This Row],[End Date]]-Project_Tracker[[#This Row],[Target Date]] -> 0 | S16: =IF(Project_Tracker[[#This Row],[Project Lead]]="", "", IFERROR(VLOOKUP(Project_Tracker[[#This Row],[Project Lead]], Setting!C:D, 2, 0), "")) -> aldy_rienaldy@banpuindo.co.id | U16: =Project_Tracker[[#This Row],[Project Lead]]&", "&Project_Tracker[[#This Row],[Team Collaboration]] -> ALR, ARS | AC16: 2025
A17: 17 | B17: Management System | C17: BP-Organization Alignment and QMS as aggreed planned (based on the poin 4) | D17: MS 5.2 | E17: JBG Pre-Closure and MineClosure | F17: RRP | G17: ALR | H17: 1 | I17: Q1-H1 | L17: Completed | M17: 1. Already develop BP Level 0,1,2 Pre Closure and Mine Closure Version in Visio Format 2. Organization Structure Process by HR | S17: =IF(Project_Tracker[[#This Row],[Project Lead]]="", "", IFERROR(VLOOKUP(Project_Tracker[[#This Row],[Project Lead]], Setting!C:D, 2, 0), "")) -> ratih_putri@banpuindo.co.id | U17: =Project_Tracker[[#This Row],[Project Lead]]&", "&Project_Tracker[[#This Row],[Team Collaboration]] -> RRP, ALR | AC17: 2025
A18: 18 | B18: Management System | C18: BP-Organization Alignment and QMS as aggreed planned (based on the poin 4) | D18: MS 5.3 | E18: ITM Campus | F18: ARS | G18: DHI | H18: 0.5 | I18: Q1-H1 | L18: Open | O18: Need confirmation with HR (Aligned with Khatulistiwa) | S18: =IF(Project_Tracker[[#This Row],[Project Lead]]="", "", IFERROR(VLOOKUP(Project_Tracker[[#This Row],[Project Lead]], Setting!C:D, 2, 0), "")) -> aditya_r@banpuindo.co.id | U18: =Project_Tracker[[#This Row],[Project Lead]]&", "&Project_Tracker[[#This Row],[Team Collaboration]] -> ARS, DHI | AC18: 2025
A19: 19 | B19: Management System | C19: BP-Organization Alignment and QMS as aggreed planned (based on the poin 4) | D19: MS 5.4 | E19: Corporate Secretary and Legal | F19: RRP | G19: ARS | H19: 1 | I19: Q2-H1 | L19: Completed | M19: 1. Already develop BP Level 1,2, Flow Process Detail, and RASCI Summary for Corsec and Legal 2. Already sent the BP document to HR and Corsec Legal team 3. Already joined Kick Off Meeting with Korn Ferry and team 4. Support KF Team regarding some concern related BP and RASCI 5. Sharing how to develop BP and Flow Process based on ITM Standard to KF Team 6. Prepare BP analyze and reccomendation for Record Management 7. Facilitate process owner to review BP and Flow Process to decide using KF version or ITM version 8. Monitor and tracking progress of BP and Flow Process completion that delivered by KF 9. Facilitate process owner to review BP outstanding (Litigation, IPR, Record Management) 10. Confirmation to PO for reviewing update BP from KF | S19: =IF(Project_Tracker[[#This Row],[Project Lead]]="", "", IFERROR(VLOOKUP(Project_Tracker[[#This Row],[Project Lead]], Setting!C:D, 2, 0), "")) -> ratih_putri@banpuindo.co.id | U19: =Project_Tracker[[#This Row],[Project Lead]]&", "&Project_Tracker[[#This Row],[Team Collaboration]] -> RRP, ARS | AC19: 2025
A20: 20 | B20: Management System | C20: BP-Organization Alignment and QMS as aggreed planned (based on the poin 4) | D20: MS 5.5 | E20: Information Technology | F20: DHI | G20: ARS | H20: 1 | I20: 45681 | J20: 45658 | K20: 45681 | L20: Completed | M20: -already develop operating model - already develop BP LVL 1 IT Division - Already develop BP LVL 2 DATA & AI - Already develop BP LVL 2 Governance & Assurance - Already develop BP LVL 2 Strategy & Architect - Already Develop BP LVL 2 Service & Infra - Already Develop BP LVL 2 IT Development & Implementation | N20: BP Approval Process | O20: N/A | P20: =Project_Tracker[[#This Row],[End Date]]-Project_Tracker[[#This Row],[Target Date]] -> 0 | S20: =IF(Project_Tracker[[#This Row],[Project Lead]]="", "", IFERROR(VLOOKUP(Project_Tracker[[#This Row],[Project Lead]], Setting!C:D, 2, 0), "")) -> dhany_indraswara@banpuindo.co.id | U20: =Project_Tracker[[#This Row],[Project Lead]]&", "&Project_Tracker[[#This Row],[Team Collaboration]] -> DHI, ARS | AC20: 2025
A21: 21 | B21: Management System | C21: BP-Organization Alignment and QMS as aggreed planned (based on the poin 4) | D21: MS 5.6 | E21: MSBP | F21: ALR | G21: ARS, RRP, DHI, RSW, BEY | H21: 0.73 | I21: 45930 | J21: 45323 | K21: 45930 | L21: Progress | M21: 1. Already developed BP L2-3 MS, BP, CM, CI 2. Already developed Detail Flow Process + RASCI 3. Already identified the required governance 4. Already drafted for several SOP related MS, BP, CM, CI 5. Already conducted discussion with MSBP Head regarding project timeline and scope 6. Already completed for MS SOP | N21: 1. Continue Review Serial SOP of MSBP 2. Monitor for CI Governance development 3. Continue develop for MS Document in Management System Area | O21: N/A | P21: =Project_Tracker[[#This Row],[End Date]]-Project_Tracker[[#This Row],[Target Date]] -> 0 | S21: =IF(Project_Tracker[[#This Row],[Project Lead]]="", "", IFERROR(VLOOKUP(Project_Tracker[[#This Row],[Project Lead]], Setting!C:D, 2, 0), "")) -> aldy_rienaldy@banpuindo.co.id | U21: =Project_Tracker[[#This Row],[Project Lead]]&", "&Project_Tracker[[#This Row],[Team Collaboration]] -> ALR, ARS, RRP, DHI, RSW, BEY | AC21: 2025
A22: 22 | B22: Management System | C22: BP-Organization Alignment and QMS as aggreed planned (based on the poin 4) | D22: MS 5.7 | E22: Coal Sales & Trading | F22: RRP | G22: ARS | H22: 1 | I22: Q2-H1 | L22: Completed | M22: 1. Drafting Project Charter 2. Conduct Kick Off Meeting on 24 July 2025 3. Review Current Business Process for Domestic Sales, SCQM, Sales Logistic Services, and Coal Trading 4. Develop CST Business Process Level 1-3 5. Conduct internal alignment meeting 6. Send update progress report 7. Wrap up summary and reccomendation | S22: =IF(Project_Tracker[[#This Row],[Project Lead]]="", "", IFERROR(VLOOKUP(Project_Tracker[[#This Row],[Project Lead]], Setting!C:D, 2, 0), "")) -> ratih_putri@banpuindo.co.id | U22: =Project_Tracker[[#This Row],[Project Lead]]&", "&Project_Tracker[[#This Row],[Team Collaboration]] -> RRP, ARS | AC22: 2025
A23: 23 | B23: Management System | C23: BP-Organization Alignment and QMS as aggreed planned (based on the poin 4) | D23: MS 5.8 | E23: Melak Cluster Enhancement | F23: ALR | G23: ARS, RRP, DHI | H23: 0.79 | I23: 45838 | J23: 45708 | K23: 45838 | L23: Progress | M23: 1. Already conducted Stage 1 (BP Workshop) 2. Already conducted Stage 2 (MS Workshop) 3. Already conducted review and alignment for the BP Design 4. Already coordinate and remind target with DSPM - for operational basis in SOP development 5. Already conducted further discussion regarding Coal Processing process - align with IBU 6. Already conducted socialization agenda to All TCM-BEK related stakeholders regarding BP Level 0 Mapping 7. Already continued the project by giving the TCM & BEK BP to Consultant Team 8. Already ensure and monitor the implementation of MELAK BP Development by Consultant Team | N23: 1. Need to Finalize the ITM High Level Business Process 2. Ensure the socialization of the final deliverables of MELAK BP to all MELAK respective stakeholders 3. Implement the next phase of Governance development | O23: N/A | P23: =Project_Tracker[[#This Row],[End Date]]-Project_Tracker[[#This Row],[Target Date]] -> 0 | S23: =IF(Project_Tracker[[#This Row],[Project Lead]]="", "", IFERROR(VLOOKUP(Project_Tracker[[#This Row],[Project Lead]], Setting!C:D, 2, 0), "")) -> aldy_rienaldy@banpuindo.co.id | U23: =Project_Tracker[[#This Row],[Project Lead]]&", "&Project_Tracker[[#This Row],[Team Collaboration]] -> ALR, ARS, RRP, DHI | AC23: 2025
A24: 24 | B24: Management System | C24: BP-Organization Alignment and QMS as aggreed planned (based on the poin 4) | D24: MS 5.9 | E24: IEU | F24: RRP | G24: ALR | H24: 0.2 | I24: Q3-H2 | L24: Hold | O24: Still waiting key deliverables of Katulistiwa Project | S24: =IF(Project_Tracker[[#This Row],[Project Lead]]="", "", IFERROR(VLOOKUP(Project_Tracker[[#This Row],[Project Lead]], Setting!C:D, 2, 0), "")) -> ratih_putri@banpuindo.co.id | U24: =Project_Tracker[[#This Row],[Project Lead]]&", "&Project_Tracker[[#This Row],[Team Collaboration]] -> RRP, ALR | AC24: 2025
A25: 25 | B25: Management System | C25: BP-Organization Alignment and QMS as aggreed planned (based on the poin 4) | D25: MS 5.1 | E25: TRUST (BP & Organization) | F25: ARS | G25: ALR, DHI, RRP | H25: 0 | I25: Q3-H2 | L25: Open | M25: Waiting for ITM & Melak Operating Model and Business Process Enhancement | O25: Still waiting key deliverables of Katulistiwa Project | S25: =IF(Project_Tracker[[#This Row],[Project Lead]]="", "", IFERROR(VLOOKUP(Project_Tracker[[#This Row],[Project Lead]], Setting!C:D, 2, 0), "")) -> aditya_r@banpuindo.co.id | U25: =Project_Tracker[[#This Row],[Project Lead]]&", "&Project_Tracker[[#This Row],[Team Collaboration]] -> ARS, ALR, DHI, RRP | AC25: 2025
A26: 26 | B26: Management System | C26: BP-Organization Alignment and QMS as aggreed planned (based on the poin 4) | D26: MS 5.11 | E26: Port Organization (New Business)/IBU | F26: ARS | G26: DHI | H26: 0.85 | I26: Q4-H2 | J26: 45677 | K26: 46021 | L26: Progress | M26: 1. BP Lvl 0 IBU & Logistic has developed 2. BP Lvl 1-2 IBU & Logistic has developed 3. BP Lvl 3 IBU & Logistic 85% developed 4. Waiting for IBU & Logistic business structure (Sub Holding) | N26: Still waiting key deliverables of Katulistiwa Project, prepare DOA Identification Matrix for Interim and Operational, Confirmation DOA from Coal Trading for Quaotation to customer | S26: =IF(Project_Tracker[[#This Row],[Project Lead]]="", "", IFERROR(VLOOKUP(Project_Tracker[[#This Row],[Project Lead]], Setting!C:D, 2, 0), "")) -> aditya_r@banpuindo.co.id | U26: =Project_Tracker[[#This Row],[Project Lead]]&", "&Project_Tracker[[#This Row],[Team Collaboration]] -> ARS, DHI | AC26: 2025
A27: 28 | B27: Management System | C27: BP-Organization Alignment and QMS as aggreed planned (based on the poin 4) | D27: MS 5.13 | E27: BP-Organization Alignment and QMS as aggreed planned (based on the poin 4) | F27: ALR | G27: DHI | H27: 1 | I27: 45852 | J27: 45719 | K27: 45852 | L27: Completed | M27: 1. Already confirmed the project objective and scope 2. Conduct Kick-Off Meeting 3. Finalized SIPOC Table 4. Developed FSP BP, Identify PPI 5. Already develop Flow Process + RASCI (18/18) 6. Identified the requirements for Procedure Development 7. Already developed Procedure and Derivative (SOP)* 8. Review and Finalization of Procedure | N27: 1. Conduct sircular approval of documents | P27: =Project_Tracker[[#This Row],[End Date]]-Project_Tracker[[#This Row],[Target Date]] -> 0 | S27: =IF(Project_Tracker[[#This Row],[Project Lead]]="", "", IFERROR(VLOOKUP(Project_Tracker[[#This Row],[Project Lead]], Setting!C:D, 2, 0), "")) -> aldy_rienaldy@banpuindo.co.id | U27: =Project_Tracker[[#This Row],[Project Lead]]&", "&Project_Tracker[[#This Row],[Team Collaboration]] -> ALR, DHI | AC27: 2025
A28: 29 | B28: Management System | C28: BP-Organization Alignment and QMS as aggreed planned (based on the poin 4) | D28: MS 5.14 | E28: Community Development (Process & System) | F28: DHI | G28: ALR | H28: 0 | I28: 45838 | L28: Hold | S28: =IF(Project_Tracker[[#This Row],[Project Lead]]="", "", IFERROR(VLOOKUP(Project_Tracker[[#This Row],[Project Lead]], Setting!C:D, 2, 0), "")) -> dhany_indraswara@banpuindo.co.id | U28: =Project_Tracker[[#This Row],[Project Lead]]&", "&Project_Tracker[[#This Row],[Team Collaboration]] -> DHI, ALR | AC28: 2025
A29: 31 | B29: Management System | C29: BP-Organization Alignment and QMS as aggreed planned (based on the poin 4) | D29: MS 5.16 | E29: IBO Enhancement | F29: RRP | G29: ALR | H29: 0.1 | I29: Q2-H1 | L29: Hold | M29: - Conduct follow up discussion - Share project overvier template - Encourage to provide Business Canvas Model as Strategic Context PT IBO | O29: Still waiting key deliverables of Katulistiwa Project | S29: =IF(Project_Tracker[[#This Row],[Project Lead]]="", "", IFERROR(VLOOKUP(Project_Tracker[[#This Row],[Project Lead]], Setting!C:D, 2, 0), "")) -> ratih_putri@banpuindo.co.id | U29: =Project_Tracker[[#This Row],[Project Lead]]&", "&Project_Tracker[[#This Row],[Team Collaboration]] -> RRP, ALR | AC29: 2025
A30: 32 | B30: Management System | C30: BP-Organization Alignment and QMS as aggreed planned (based on the poin 4) | D30: MS 5.17 | E30: SCM Project (Mahakam Project) | F30: ARS | G30: ALR, RRP, DHI | H30: 0.85 | I30: H1-H2 | L30: Progress | M30: Workshop Offline To-Be Process Aligned with all PO already conducted at IBO | N30: Develop standard procedure for SCM process | S30: =IF(Project_Tracker[[#This Row],[Project Lead]]="", "", IFERROR(VLOOKUP(Project_Tracker[[#This Row],[Project Lead]], Setting!C:D, 2, 0), "")) -> aditya_r@banpuindo.co.id | U30: =Project_Tracker[[#This Row],[Project Lead]]&", "&Project_Tracker[[#This Row],[Team Collaboration]] -> ARS, ALR, RRP, DHI | AC30: 2025
A31: 32 | B31: Management System | C31: BP-Organization Alignment and QMS as aggreed planned (based on the poin 4) | D31: MS 5.17 | E31: SCM Project (as Transformation Team) | F31: ALR | G31: ARS, RRP, DHI | H31: 1 | I31: H1-H2 | L31: Completed | M31: 1. Already confirmed the project objective and scope 2. Conduct Kick-Off Meeting 3. Identified the requirements for Procedure Development 4. Already developed Procedure and Derivative (SOP)* 5. Review and Finalization of Procedure | N31: 1. Conduct sircular approval of documents | AC31: 2025
A32: 33 | B32: Management System | C32: BP-Organization Alignment and QMS as aggreed planned (based on the poin 4) | D32: MS 5.18 | E32: OS - Q P B Plan & Revision (MS & SOP) | F32: ARS | H32: 0.8 | I32: Q2-H1 | J32: 45684 | K32: 46019 | L32: Progress | M32: 1. SOP for QPB revision already developed 2. SOP for QBP Actual already drafted | N32: Develop Management Standard for QPB Process | S32: =IF(Project_Tracker[[#This Row],[Project Lead]]="", "", IFERROR(VLOOKUP(Project_Tracker[[#This Row],[Project Lead]], Setting!C:D, 2, 0), "")) -> aditya_r@banpuindo.co.id | U32: =Project_Tracker[[#This Row],[Project Lead]]&", "&Project_Tracker[[#This Row],[Team Collaboration]] -> ARS, | AC32: 2025
A33: 34 | B33: Management System | C33: BP-Organization Alignment and QMS as aggreed planned (based on the poin 4) | D33: MS 5.19 | E33: Contractor Management & Engineering Enhancement (BP) | F33: ARS | H33: 1 | I33: Q2-H1 | J33: 45663 | K33: 45743 | L33: Completed | M33: 1. BP Lvl 1-2 CMEE has developed 2. BP Lvl 3 (detail flow) has developed 3. SP for Contractor Type has developed | S33: =IF(Project_Tracker[[#This Row],[Project Lead]]="", "", IFERROR(VLOOKUP(Project_Tracker[[#This Row],[Project Lead]], Setting!C:D, 2, 0), "")) -> aditya_r@banpuindo.co.id | U33: =Project_Tracker[[#This Row],[Project Lead]]&", "&Project_Tracker[[#This Row],[Team Collaboration]] -> ARS, | AC33: 2025
A34: 35 | B34: Management System | C34: BP-Organization Alignment and QMS as aggreed planned (based on the poin 4) | D34: MS 5.20 | E34: ITMP Phase 3 | F34: ARS | H34: 0 | I34: Q2-H1 | L34: Open | S34: =IF(Project_Tracker[[#This Row],[Project Lead]]="", "", IFERROR(VLOOKUP(Project_Tracker[[#This Row],[Project Lead]], Setting!C:D, 2, 0), "")) -> aditya_r@banpuindo.co.id | U34: =Project_Tracker[[#This Row],[Project Lead]]&", "&Project_Tracker[[#This Row],[Team Collaboration]] -> ARS, | AC34: 2025
A35: 36 | B35: Management System | C35: Facilitating Digital Project on Standardization/Formalization (Aligned with Digital Initiatives) as collaborated with Innovation Team | D35: MS 6.1 | E35: Invoice Management System | F35: ALR | G35: BEY | H35: 0 | I35: H1-H2 | L35: Open | S35: =IF(Project_Tracker[[#This Row],[Project Lead]]="", "", IFERROR(VLOOKUP(Project_Tracker[[#This Row],[Project Lead]], Setting!C:D, 2, 0), "")) -> aldy_rienaldy@banpuindo.co.id | U35: =Project_Tracker[[#This Row],[Project Lead]]&", "&Project_Tracker[[#This Row],[Team Collaboration]] -> ALR, BEY | AC35: 2025
A36: 37 | B36: Management System | C36: Facilitating Digital Project on Standardization/Formalization (Aligned with Digital Initiatives) as collaborated with Innovation Team | D36: MS 6.2 | E36: Melak Integrated Mine Planning | F36: ALR | G36: AFZ | H36: 1 | I36: H1-H2 | L36: Completed | M36: 1. Already draft BP as Khatulistiwa Project Result 2. Clarify and Validate BP LOMP & 5YRP 3. Clarify and Validate BP Annual Planning 4. Clarify and Validate BP 3MRP & Monthly Planning 5. Done for Alignment with OS, MED, ERSM, HSEC, CBIC 6. Done for RASCI Development | N36: 1. Confirm the RASCI and OD with HR | S36: =IF(Project_Tracker[[#This Row],[Project Lead]]="", "", IFERROR(VLOOKUP(Project_Tracker[[#This Row],[Project Lead]], Setting!C:D, 2, 0), "")) -> aldy_rienaldy@banpuindo.co.id | U36: =Project_Tracker[[#This Row],[Project Lead]]&", "&Project_Tracker[[#This Row],[Team Collaboration]] -> ALR, AFZ | AC36: 2025
A37: 38 | B37: Management System | C37: Facilitating Digital Project on Standardization/Formalization (Aligned with Digital Initiatives) as collaborated with Innovation Team | D37: MS 6.3 | E37: SSO – Blending Optimization | F37: ARS | G37: ALR, RSW | H37: 0.9 | I37: 45925 | J37: 45839 | K37: 46009 | L37: Progress | M37: Already set up role play and alignment with all stakeholders for SOP SSO | N37: To revise and finalize SOP SSO according to role play result | S37: =IF(Project_Tracker[[#This Row],[Project Lead]]="", "", IFERROR(VLOOKUP(Project_Tracker[[#This Row],[Project Lead]], Setting!C:D, 2, 0), "")) -> aditya_r@banpuindo.co.id | U37: =Project_Tracker[[#This Row],[Project Lead]]&", "&Project_Tracker[[#This Row],[Team Collaboration]] -> ARS, ALR, RSW | AC37: 2025
A38: 40 | B38: Management System | C38: Facilitating Digital Project on Standardization/Formalization (Aligned with Digital Initiatives) as collaborated with Innovation Team | D38: MS 6.5 | E38: Data Governance (3 Project) - Master Data (OS Project) - Coal Inventory - ITM Data Governance for OS Project | F38: DHI | G38: AFZ | H38: 1 | I38: 45838 | J38: 45720 | K38: 45808 | L38: Completed | M38: -Build WBS for the rest of project -Study the data governance document - Get the details of activity WBS for MSBP task -Already develop project charter -'-As-Is process analysis & Gap Analysis 'Doing sprint implement for all project - Master Data (OS Project) - Coal Inventory - ITM Data Governance for OS Project POC Activity for truck scale project | N38: -Approval document ITM (Fully Approved) & BEK -Adoption Process (Training, Communication, Utilization for TS) | S38: =IF(Project_Tracker[[#This Row],[Project Lead]]="", "", IFERROR(VLOOKUP(Project_Tracker[[#This Row],[Project Lead]], Setting!C:D, 2, 0), "")) -> dhany_indraswara@banpuindo.co.id | U38: =Project_Tracker[[#This Row],[Project Lead]]&", "&Project_Tracker[[#This Row],[Team Collaboration]] -> DHI, AFZ | AC38: 2025
B39: Management System | C39: Facilitating Digital Project on Standardization/Formalization (Aligned with Digital Initiatives) as collaborated with Innovation Team | D39: MS 6.6 | E39: Tug Management System Standardization | F39: DHI | G39: AFZ | H39: 1 | I39: 45869 | J39: 45782 | K39: 45808 | L39: Completed | M39: -Already initial meeting with SC team '-Detail meeting to get details target -Details deliverables project for prodedure (TMS Charter) -Already build 5 Business Process flow based on system analysis. -- Need to clarify & Discuss with PO to get the final business process flow -Build SOP for new process flow (6 SOP + 2 WI) | N39: - Continue the activity with pak chrisna weekly SOP Barge Operation Compliance -> Review Pak Chrisna STS Transhipment -> Review pak Chrisna WI: Shipper Representative -> Approval Guideline TMS -> Tug & Boat owner & Master (By Manual book) | S39: =IF(Project_Tracker[[#This Row],[Project Lead]]="", "", IFERROR(VLOOKUP(Project_Tracker[[#This Row],[Project Lead]], Setting!C:D, 2, 0), "")) -> dhany_indraswara@banpuindo.co.id | U39: =Project_Tracker[[#This Row],[Project Lead]]&", "&Project_Tracker[[#This Row],[Team Collaboration]] -> DHI, AFZ | AC39: 2025
B40: Management System | C40: Facilitating Digital Project on Standardization/Formalization (Aligned with Digital Initiatives) as collaborated with Innovation Team | D40: MS 6.7 | E40: Data Management for ITM Group Level | F40: DHI | G40: AFZ | H40: 1 | I40: 45991 | J40: 45782 | K40: 45808 | L40: Completed | M40: -Meeting with all stakeholder to get the insight -Build framework to guide the development -Analyze DAMA Box to standardize the system -Already build framework go build MS - Build WBS for detailed project - Build project charter (finalized) -'-Development MS ('- Build MS with process owner 2x/week) 8% - Policy Review | N40: -Final review with process owner (pak Amang & pak Muhardian) -Meet with HR & MSBP to build change culture klausul (reschedule)** | S40: =IF(Project_Tracker[[#This Row],[Project Lead]]="", "", IFERROR(VLOOKUP(Project_Tracker[[#This Row],[Project Lead]], Setting!C:D, 2, 0), "")) -> dhany_indraswara@banpuindo.co.id | U40: =Project_Tracker[[#This Row],[Project Lead]]&", "&Project_Tracker[[#This Row],[Team Collaboration]] -> DHI, AFZ | AC40: 2025
...

Sheet Setting
A1: Status | C1: Name | D1: Email
A2: Open | C2: RRP | D2: ratih_putri@banpuindo.co.id
A3: Completed | C3: DHI | D3: dhany_indraswara@banpuindo.co.id
A4: Hold | C4: BEY | D4: bella_yolanda@banpuindo.co.id
A5: Progress | C5: ASN | D5: andri_s@banpuindo.co.id
C6: RSW | D6: reza_suryawardhana@banpuindo.co.id
C7: ALR | D7: aldy_rienaldy@banpuindo.co.id
C8: ARS | D8: aditya_r@banpuindo.co.id
C9: AFZ | D9: afrizon_afrizon@banpuindo.co.id
